NameError
Python 3.6.5: F:\Python3.6.5_V2\python.exe
Mon Mar 30 09:56:59 2020

A problem occurred in a Python script.  Here is the sequence of
function calls leading up to the error, in the order they occurred.

 D:\My_Codes\easylearn-fmri\eslearn\gui_test\easylearn_data_loading_run.py in load_configuration(self=<__main__.EasylearnDataLoadingRun object>)
  151                 QMessageBox.warning( self, 'Warning', f'{self.configuration_file} is not valid JSON')
  152                 self.configuration_file = ""
  153                 a
  154                 self.set_run_appearance()
  155         else:
a undefined
NameError: name 'a' is not defined
    __cause__ = None
    __class__ = <class 'NameError'>
    __context__ = JSONDecodeError('Expecting value: line 1 column 1 (char 0)',)
    __delattr__ = <method-wrapper '__delattr__' of NameError object>
    __dict__ = {}
    __dir__ = <built-in method __dir__ of NameError object>
    __doc__ = 'Name not found globally.'
    __eq__ = <method-wrapper '__eq__' of NameError object>
    __format__ = <built-in method __format__ of NameError object>
    __ge__ = <method-wrapper '__ge__' of NameError object>
    __getattribute__ = <method-wrapper '__getattribute__' of NameError object>
    __gt__ = <method-wrapper '__gt__' of NameError object>
    __hash__ = <method-wrapper '__hash__' of NameError object>
    __init__ = <method-wrapper '__init__' of NameError object>
    __init_subclass__ = <built-in method __init_subclass__ of type object>
    __le__ = <method-wrapper '__le__' of NameError object>
    __lt__ = <method-wrapper '__lt__' of NameError object>
    __ne__ = <method-wrapper '__ne__' of NameError object>
    __new__ = <built-in method __new__ of type object>
    __reduce__ = <built-in method __reduce__ of NameError object>
    __reduce_ex__ = <built-in method __reduce_ex__ of NameError object>
    __repr__ = <method-wrapper '__repr__' of NameError object>
    __setattr__ = <method-wrapper '__setattr__' of NameError object>
    __setstate__ = <built-in method __setstate__ of NameError object>
    __sizeof__ = <built-in method __sizeof__ of NameError object>
    __str__ = <method-wrapper '__str__' of NameError object>
    __subclasshook__ = <built-in method __subclasshook__ of type object>
    __suppress_context__ = False
    __traceback__ = <traceback object>
    args = ("name 'a' is not defined",)
    with_traceback = <built-in method with_traceback of NameError object>

The above is a description of an error in a Python program.  Here is
the original traceback:

Traceback (most recent call last):
  File ".\easylearn_data_loading_run.py", line 122, in load_configuration
    self.configuration = json.loads(self.configuration)
  File "F:\Python3.6.5_V2\lib\json\__init__.py", line 354, in loads
    return _default_decoder.decode(s)
  File "F:\Python3.6.5_V2\lib\json\decoder.py", line 339, in decode
    obj, end = self.raw_decode(s, idx=_w(s, 0).end())
  File "F:\Python3.6.5_V2\lib\json\decoder.py", line 357, in raw_decode
    raise JSONDecodeError("Expecting value", s, err.value) from None
json.decoder.JSONDecodeError: Expecting value: line 1 column 1 (char 0)

During handling of the above exception, another exception occurred:

Traceback (most recent call last):
  File ".\easylearn_data_loading_run.py", line 153, in load_configuration
    a
NameError: name 'a' is not defined

